<?xml version="1.0"?>
<robot xmlns:xacro="http://www.ros.org/wiki/xacro">

  <xacro:include filename="inertial_macros.xacro" />
    <material name="white">
        <color rgba="1.0 1.0 1.0 1.0"/>
    </material>
    <material name="orange">
        <color rgba="1.0 0.3 0.1 1.0"/>
    </material>
    <material name="blue">
        <color rgba="0.2 0.2 1.0 1.0"/>
    </material>
    <material name="black">
        <color rgba="0.0 0.0 0.0 1.0"/>
    </material>
    <material name="wolf-yellow">
        <color rgba="1 0.9373 0.1372 1" />
    </material>
    <material name="wolf-gray">
        <color rgba="0.2 0.2 0.2 1" />
    </material>      
    <material name="wolf-lidar">
        <color rgba="0.792156862745098 0.819607843137255 0.933333333333333 1" />
    </material>     
    <material name="wolf-tire">
        <color rgba="0.4 0.4 0.4 1" />
    </material>  
    
<!-- =============================================== -->

    <link name="base_link"></link>

    <joint name="chassis_joint" type="fixed">
        <origin xyz="0 0 0.03173" rpy="0.0 0.0 0.0"/>
        <parent link="base_link"/>
        <child link="chassis"/>
    </joint>
    <link name="chassis">
        <visual name="">
            <origin xyz="0 0 0.03713" rpy="0 0 0" />
            <geometry>
                <box size= "0.2625 0.180 0.08074" />
            </geometry>
            <material name="wolf-gray">
                <color rgba="1.0 0.0 0.0 1.0"/>
                <texture filename=""/>
            </material>
        </visual>
        <collision>
            <origin xyz="0 0 0.03713" rpy="0 0 0" />
            <geometry>
                <box size= "0.2625 0.180 0.08074" />
            </geometry>
        </collision>
        <xacro:inertial_box mass="0.5" x="0.2625" y="0.180" z="0.08074">
        <origin xyz="0 0 0.03713" rpy="0 0 0"/>
        </xacro:inertial_box>
    </link> 
    <gazebo reference="chassis">
        <material>Gazebo/Black</material>
    </gazebo>  

<!-- TOP PLATE LINK -->
   <joint name="top_plate_joint" type="fixed">
     <parent link="chassis"/>
     <child link="top_plate_link"/>
     <origin xyz = "0 0 0" />
   </joint>

  <link name="top_plate_link">
    <visual>
      <origin xyz="0 0 0.08074" rpy="0 0 0" />
      <geometry>
        <box size= "0.278 0.226 0.002" />
      </geometry>
      <material name="wolf-yellow">
      </material>
    </visual>
    <collision>
      <origin xyz="0 0 0.08074" rpy="0 0 0" />
      <geometry>
        <box size= "0.278 0.226 0.002" />
      </geometry>
    </collision>    
    <xacro:inertial_box mass="0.5" x="0.278" y="0.226" z="0.002">
      <origin xyz="0 0 0.08074" rpy="0 0 0"/>
    </xacro:inertial_box>
  </link>  
  <gazebo reference="top_plate_link">
    <material>Gazebo/Yellow</material>
  </gazebo>  

<!-- BACK HOLDER LINK -->
   <joint name="back_holder_joint" type="fixed">
     <parent link="chassis"/>
     <child link="back_holder_link"/>
     <origin xyz = "0 0 0" />
   </joint>

  <link name="back_holder_link">
    <visual>
      <origin xyz="-0.086 0 0.1204" rpy="0 0 0" />
      <geometry>
        <box size= "0.050 0.18 0.083" />
      </geometry>
      <material name="wolf-gray">
      </material>
    </visual>
    <collision>
      <origin xyz="-0.086 0 0.1204" rpy="0 0 0" />
      <geometry>
        <box size= "0.050 0.18 0.083" />
      </geometry>
    </collision>    
    <xacro:inertial_box mass="0.5" x="0.050" y="0.18" z="0.083">
      <origin xyz="-0.086 0 0.1204" rpy="0 0 0" />
    </xacro:inertial_box>    
  </link>    
  <gazebo reference="back_holder_link">
    <material>Gazebo/DarkGrey</material>
  </gazebo>

 <!-- FRONT RIGHT WHEEL -->
  <joint name="front_right_joint" type="continuous">
    <parent link="base_link" />
    <child link="front_right_link" />
    <origin 
      xyz="0.089999999918902 -0.120145200302238 0.0525"
      rpy="${pi/2} 0 0" />
    <axis xyz="0 0 -1" />
  </joint>

  <link name="front_right_link">
    <visual>
      <geometry>
        <cylinder radius="0.0525" length="0.053" />
      </geometry>
      <material name="wolf-tire">
      </material>
    </visual>
    <collision>
      <geometry>
        <cylinder radius="0.0525" length="0.053" />
      </geometry>
    </collision>    
    <xacro:inertial_cylinder mass="0.5" radius="0.0525" length="0.053">
      <origin xyz="0 0 0" rpy="0 0 0" />
    </xacro:inertial_cylinder>       
  </link>
  <gazebo reference="front_right_link">
    <material>Gazebo/Grey</material>
  </gazebo>  

  <!-- FRONT LEFT WHEEL -->
  <joint name="front_left_joint" type="continuous">
    <parent link="base_link" />
    <child link="front_left_link" />
    <origin 
      xyz="0.089999999918902 0.120145200302238 0.0525"
      rpy="-${pi/2} 0 0" />
    <axis xyz="0 0 1" />
  </joint>

  <link name="front_left_link">
    <visual>
      <geometry>
        <cylinder radius="0.0525" length="0.053" />
      </geometry>
      <material name="wolf-tire">
      </material>
    </visual>
    <collision>
      <geometry>
        <cylinder radius="0.0525" length="0.053" />
      </geometry>
    </collision>    
    <xacro:inertial_cylinder mass="0.5" radius="0.0525" length="0.053">
      <origin xyz="0 0 0" rpy="0 0 0" />
    </xacro:inertial_cylinder>           
  </link>
  <gazebo reference="front_left_link">
    <material>Gazebo/Grey</material>
  </gazebo>  

<!-- BACK RIGHT WHEEL -->
  <joint name="back_right_joint" type="continuous">
    <parent link="base_link" />
    <child link="back_right_link" />
    <origin 
      xyz="-0.089999999918902 -0.120145200302238 0.0525"
      rpy="${pi/2} 0 0" />
    <axis xyz="0 0 -1" />
  </joint>

  <link name="back_right_link">
    <visual>
      <geometry>
        <cylinder radius="0.0525" length="0.053" />
      </geometry>
      <material name="wolf-tire">
      </material>
    </visual>
    <collision>
      <geometry>
        <cylinder radius="0.0525" length="0.053" />
      </geometry>
    </collision>    
    <xacro:inertial_cylinder mass="0.5" radius="0.0525" length="0.053">
      <origin xyz="0 0 0" rpy="0 0 0" />
    </xacro:inertial_cylinder>           
  </link>
  <gazebo reference="back_right_link">
    <material>Gazebo/Grey</material>
  </gazebo>  

  <!-- BACK LEFT WHEEL -->
  <joint name="back_left_joint" type="continuous">
    <parent link="base_link" />
    <child link="back_left_link" />
    <origin 
      xyz="-0.089999999918902 0.120145200302238 0.0525"
      rpy="-${pi/2} 0 0" />
    <axis xyz="0 0 1" />
  </joint>

  <link name="back_left_link">
    <visual>
      <geometry>
        <cylinder radius="0.0525" length="0.053" />
      </geometry>
      <material name="wolf-tire">
      </material>
    </visual>
    <collision>
      <geometry>
        <cylinder radius="0.0525" length="0.053" />
      </geometry>
    </collision>    
    <xacro:inertial_cylinder mass="0.5" radius="0.0525" length="0.053">
      <origin xyz="0 0 0" rpy="0 0 0" />
    </xacro:inertial_cylinder>           
  </link>
  <gazebo reference="back_left_link">
    <material>Gazebo/Grey</material>
  </gazebo>  

</robot>